Workbook
Name Calendar_Type: Settings!$B$3
Name Cycle_Header: Settings!$B$7
Name Days_per_Cycle: Settings!$B$4
Name End_Date_of_Year: Settings!$B$6
Name Number_Of_Weekends: Settings!$B$9
Name Start_Date_of_Year: Settings!$B$5
Name Weekend_As_Holiday: Settings!$B$8

Sheet Cycle Calendar
A1: Cycle Calendar | E1: Cycle Header: | F1: ="CY"&Cycle_Header -> CY2026 | H1: How to use this template: 1. Enter all holidays in the Holidays worksheet Note: All National and Legal holidays are already indicated but you may also enter your company holidays (e.g. outing) 2. In the Settings worksheet, choose the type of calendar that your company uses (i.e. Cycle-Based or Calendar-Based) 3. Enter the Start and End Date of your business calendar 4. Verify the # of Days and the inclusive dates per cycle below 5. Save the Cycle Calendar template file and email it to sfe.support@electronicscience.com
A2: Cycle | B2: Zone | C2: Day | D2: Cycle Date | E2: Type | F2: Label
A3: (type: integer | size: 2) | B3: (type: integer | size: 2) | C3: (type: integer | size: 2) | D3: (type: date | size: 10) | E3: (type: text | size: 1) | F3: (type: text | size: 3)
A4: 1, 2, 3, 4, etc. | B4: 1, 2, 3, 4, etc. | C4: 1, 2, 3, 4, etc. | D4: format: YYYY-MM-DD | E4: (e.g. R, W, H) | F4: (e.g. R1, R2, W1, H1, etc.)
A5: Valid Characters: Numeric , / | B5: Valid Characters: Numeric , / | C5: Valid Characters: Numeric , / | D5: Valid Characters: Numeric , / | E5: Valid Characters: Alphanumeric | F5: Valid Characters: Alphanumeric
A6: =IF(Calendar_Type="Calendar-Based",MONTH(D6),INT(((ROW(A1)-1)/(Days_per_Cycle+Number_Of_Weekends)))*1+1) -> 1 | B6: =IF(A6=A5,B6+1,1) -> 1 | C6: =WEEKDAY(D6,2) -> 4 | D6: =Start_Date_of_Year -> 46023 | E6: =IF(AND(OR($C6=6,$C6=7),Weekend_As_Holiday="YES",COUNTIF(Holidays!$A$6:$A$58,'Cycle Calendar'!$D6)>0),"H",IF(AND(OR($C6=6,$C6=7),Weekend_As_Holiday="NO",COUNTIF(Holidays!$A$6:$A$58,'Cycle Calendar'!$D6)>0),"W",IF(OR($C6=6,$C6=7),"W",IF(COUNTIF(Holidays!$A$6:$A$58,'Cycle Calendar'!$D6)>0,"H","R")))) -> H | F6: =E6&C6 -> H4
A7: =IF(Calendar_Type="Calendar-Based",MONTH(D7),INT(((ROW(A2)-1)/(Days_per_Cycle+Number_Of_Weekends)))*1+1) -> 1 | B7: =IF(A7=A6,B6+1,1) -> 2 | C7: =WEEKDAY(D7,2) -> 5 | D7: =D6+1 -> 46024 | E7: =IF(AND(OR($C7=6,$C7=7),Weekend_As_Holiday="YES",COUNTIF(Holidays!$A$6:$A$58,'Cycle Calendar'!$D7)>0),"H",IF(AND(OR($C7=6,$C7=7),Weekend_As_Holiday="NO",COUNTIF(Holidays!$A$6:$A$58,'Cycle Calendar'!$D7)>0),"W",IF(OR($C7=6,$C7=7),"W",IF(COUNTIF(Holidays!$A$6:$A$58,'Cycle Calendar'!$D7)>0,"H","R")))) -> H | F7: =E7&C7 -> H5
A8: =IF(Calendar_Type="Calendar-Based",MONTH(D8),INT(((ROW(A3)-1)/(Days_per_Cycle+Number_Of_Weekends)))*1+1) -> 1 | B8: =IF(A8=A7,B7+1,1) -> 3 | C8: =WEEKDAY(D8,2) -> 6 | D8: =D7+1 -> 46025 | E8: =IF(AND(OR($C8=6,$C8=7),Weekend_As_Holiday="YES",COUNTIF(Holidays!$A$6:$A$58,'Cycle Calendar'!$D8)>0),"H",IF(AND(OR($C8=6,$C8=7),Weekend_As_Holiday="NO",COUNTIF(Holidays!$A$6:$A$58,'Cycle Calendar'!$D8)>0),"W",IF(OR($C8=6,$C8=7),"W",IF(COUNTIF(Holidays!$A$6:$A$58,'Cycle Calendar'!$D8)>0,"H","R")))) -> W | F8: =E8&C8 -> W6 | H8: CYCLE | I8: # OF DAYS | J8: FROM | K8: TO | L8: HOLIDAYS
A9: =IF(Calendar_Type="Calendar-Based",MONTH(D9),INT(((ROW(A4)-1)/(Days_per_Cycle+Number_Of_Weekends)))*1+1) -> 1 | B9: =IF(A9=A8,B8+1,1) -> 4 | C9: =WEEKDAY(D9,2) -> 7 | D9: =D8+1 -> 46026 | E9: =IF(AND(OR($C9=6,$C9=7),Weekend_As_Holiday="YES",COUNTIF(Holidays!$A$6:$A$58,'Cycle Calendar'!$D9)>0),"H",IF(AND(OR($C9=6,$C9=7),Weekend_As_Holiday="NO",COUNTIF(Holidays!$A$6:$A$58,'Cycle Calendar'!$D9)>0),"W",IF(OR($C9=6,$C9=7),"W",IF(COUNTIF(Holidays!$A$6:$A$58,'Cycle Calendar'!$D9)>0,"H","R")))) -> W | F9: =E9&C9 -> W7 | H9: CYCLE 1 | I9: =COUNTIFS($D$6:$D$505,">="&Start_Date_of_Year,$D$6:$D$505,"<="&End_Date_of_Year,$A$6:$A$505,SUBSTITUTE(H9,"CYCLE ","")) -> 32 | J9: =D6 -> 46023 | K9: =J9+I9-1 -> 46054 | L9: =COUNTIFS(Holidays!$A$6:$A$58,">="&'Cycle Calendar'!J9,Holidays!$A$6:$A$58,"<="&'Cycle Calendar'!K9) -> 2
A10: =IF(Calendar_Type="Calendar-Based",MONTH(D10),INT(((ROW(A5)-1)/(Days_per_Cycle+Number_Of_Weekends)))*1+1) -> 1 | B10: =IF(A10=A9,B9+1,1) -> 5 | C10: =WEEKDAY(D10,2) -> 1 | D10: =D9+1 -> 46027 | E10: =IF(AND(OR($C10=6,$C10=7),Weekend_As_Holiday="YES",COUNTIF(Holidays!$A$6:$A$58,'Cycle Calendar'!$D10)>0),"H",IF(AND(OR($C10=6,$C10=7),Weekend_As_Holiday="NO",COUNTIF(Holidays!$A$6:$A$58,'Cycle Calendar'!$D10)>0),"W",IF(OR($C10=6,$C10=7),"W",IF(COUNTIF(Holidays!$A$6:$A$58,'Cycle Calendar'!$D10)>0,"H","R")))) -> R | F10: =E10&C10 -> R1 | H10: CYCLE 2 | I10: =COUNTIFS($D$6:$D$505,">="&Start_Date_of_Year,$D$6:$D$505,"<="&End_Date_of_Year,$A$6:$A$505,SUBSTITUTE(H10,"CYCLE ","")) -> 35 | J10: =J9+I9 -> 46055 | K10: =J10+I10-1 -> 46089 | L10: =COUNTIFS(Holidays!$A$6:$A$58,">="&'Cycle Calendar'!J10,Holidays!$A$6:$A$58,"<="&'Cycle Calendar'!K10) -> 6
A11: =IF(Calendar_Type="Calendar-Based",MONTH(D11),INT(((ROW(A6)-1)/(Days_per_Cycle+Number_Of_Weekends)))*1+1) -> 1 | B11: =IF(A11=A10,B10+1,1) -> 6 | C11: =WEEKDAY(D11,2) -> 2 | D11: =D10+1 -> 46028 | E11: =IF(AND(OR($C11=6,$C11=7),Weekend_As_Holiday="YES",COUNTIF(Holidays!$A$6:$A$58,'Cycle Calendar'!$D11)>0),"H",IF(AND(OR($C11=6,$C11=7),Weekend_As_Holiday="NO",COUNTIF(Holidays!$A$6:$A$58,'Cycle Calendar'!$D11)>0),"W",IF(OR($C11=6,$C11=7),"W",IF(COUNTIF(Holidays!$A$6:$A$58,'Cycle Calendar'!$D11)>0,"H","R")))) -> R | F11: =E11&C11 -> R2 | H11: CYCLE 3 | I11: =COUNTIFS($D$6:$D$505,">="&Start_Date_of_Year,$D$6:$D$505,"<="&End_Date_of_Year,$A$6:$A$505,SUBSTITUTE(H11,"CYCLE ","")) -> 35 | J11: =J10+I10 -> 46090 | K11: =J11+I11-1 -> 46124 | L11: =COUNTIFS(Holidays!$A$6:$A$58,">="&'Cycle Calendar'!J11,Holidays!$A$6:$A$58,"<="&'Cycle Calendar'!K11) -> 6
A12: =IF(Calendar_Type="Calendar-Based",MONTH(D12),INT(((ROW(A7)-1)/(Days_per_Cycle+Number_Of_Weekends)))*1+1) -> 1 | B12: =IF(A12=A11,B11+1,1) -> 7 | C12: =WEEKDAY(D12,2) -> 3 | D12: =D11+1 -> 46029 | E12: =IF(AND(OR($C12=6,$C12=7),Weekend_As_Holiday="YES",COUNTIF(Holidays!$A$6:$A$58,'Cycle Calendar'!$D12)>0),"H",IF(AND(OR($C12=6,$C12=7),Weekend_As_Holiday="NO",COUNTIF(Holidays!$A$6:$A$58,'Cycle Calendar'!$D12)>0),"W",IF(OR($C12=6,$C12=7),"W",IF(COUNTIF(Holidays!$A$6:$A$58,'Cycle Calendar'!$D12)>0,"H","R")))) -> R | F12: =E12&C12 -> R3 | H12: CYCLE 4 | I12: =COUNTIFS($D$6:$D$505,">="&Start_Date_of_Year,$D$6:$D$505,"<="&End_Date_of_Year,$A$6:$A$505,SUBSTITUTE(H12,"CYCLE ","")) -> 28 | J12: =J11+I11 -> 46125 | K12: =J12+I12-1 -> 46152 | L12: =COUNTIFS(Holidays!$A$6:$A$58,">="&'Cycle Calendar'!J12,Holidays!$A$6:$A$58,"<="&'Cycle Calendar'!K12) -> 1
A13: =IF(Calendar_Type="Calendar-Based",MONTH(D13),INT(((ROW(A8)-1)/(Days_per_Cycle+Number_Of_Weekends)))*1+1) -> 1 | B13: =IF(A13=A12,B12+1,1) -> 8 | C13: =WEEKDAY(D13,2) -> 4 | D13: =D12+1 -> 46030 | E13: =IF(AND(OR($C13=6,$C13=7),Weekend_As_Holiday="YES",COUNTIF(Holidays!$A$6:$A$58,'Cycle Calendar'!$D13)>0),"H",IF(AND(OR($C13=6,$C13=7),Weekend_As_Holiday="NO",COUNTIF(Holidays!$A$6:$A$58,'Cycle Calendar'!$D13)>0),"W",IF(OR($C13=6,$C13=7),"W",IF(COUNTIF(Holidays!$A$6:$A$58,'Cycle Calendar'!$D13)>0,"H","R")))) -> R | F13: =E13&C13 -> R4 | H13: CYCLE 5 | I13: =COUNTIFS($D$6:$D$505,">="&Start_Date_of_Year,$D$6:$D$505,"<="&End_Date_of_Year,$A$6:$A$505,SUBSTITUTE(H13,"CYCLE ","")) -> 28 | J13: =J12+I12 -> 46153 | K13: =J13+I13-1 -> 46180 | L13: =COUNTIFS(Holidays!$A$6:$A$58,">="&'Cycle Calendar'!J13,Holidays!$A$6:$A$58,"<="&'Cycle Calendar'!K13) -> 0
A14: =IF(Calendar_Type="Calendar-Based",MONTH(D14),INT(((ROW(A9)-1)/(Days_per_Cycle+Number_Of_Weekends)))*1+1) -> 1 | B14: =IF(A14=A13,B13+1,1) -> 9 | C14: =WEEKDAY(D14,2) -> 5 | D14: =D13+1 -> 46031 | E14: =IF(AND(OR($C14=6,$C14=7),Weekend_As_Holiday="YES",COUNTIF(Holidays!$A$6:$A$58,'Cycle Calendar'!$D14)>0),"H",IF(AND(OR($C14=6,$C14=7),Weekend_As_Holiday="NO",COUNTIF(Holidays!$A$6:$A$58,'Cycle Calendar'!$D14)>0),"W",IF(OR($C14=6,$C14=7),"W",IF(COUNTIF(Holidays!$A$6:$A$58,'Cycle Calendar'!$D14)>0,"H","R")))) -> R | F14: =E14&C14 -> R5 | H14: CYCLE 6 | I14: =COUNTIFS($D$6:$D$505,">="&Start_Date_of_Year,$D$6:$D$505,"<="&End_Date_of_Year,$A$6:$A$505,SUBSTITUTE(H14,"CYCLE ","")) -> 35 | J14: =J13+I13 -> 46181 | K14: =J14+I14-1 -> 46215 | L14: =COUNTIFS(Holidays!$A$6:$A$58,">="&'Cycle Calendar'!J14,Holidays!$A$6:$A$58,"<="&'Cycle Calendar'!K14) -> 6
A15: =IF(Calendar_Type="Calendar-Based",MONTH(D15),INT(((ROW(A10)-1)/(Days_per_Cycle+Number_Of_Weekends)))*1+1) -> 1 | B15: =IF(A15=A14,B14+1,1) -> 10 | C15: =WEEKDAY(D15,2) -> 6 | D15: =D14+1 -> 46032 | E15: =IF(AND(OR($C15=6,$C15=7),Weekend_As_Holiday="YES",COUNTIF(Holidays!$A$6:$A$58,'Cycle Calendar'!$D15)>0),"H",IF(AND(OR($C15=6,$C15=7),Weekend_As_Holiday="NO",COUNTIF(Holidays!$A$6:$A$58,'Cycle Calendar'!$D15)>0),"W",IF(OR($C15=6,$C15=7),"W",IF(COUNTIF(Holidays!$A$6:$A$58,'Cycle Calendar'!$D15)>0,"H","R")))) -> W | F15: =E15&C15 -> W6 | H15: CYCLE 7 | I15: =COUNTIFS($D$6:$D$505,">="&Start_Date_of_Year,$D$6:$D$505,"<="&End_Date_of_Year,$A$6:$A$505,SUBSTITUTE(H15,"CYCLE ","")) -> 28 | J15: =J14+I14 -> 46216 | K15: =J15+I15-1 -> 46243 | L15: =COUNTIFS(Holidays!$A$6:$A$58,">="&'Cycle Calendar'!J15,Holidays!$A$6:$A$58,"<="&'Cycle Calendar'!K15) -> 0
A16: =IF(Calendar_Type="Calendar-Based",MONTH(D16),INT(((ROW(A11)-1)/(Days_per_Cycle+Number_Of_Weekends)))*1+1) -> 1 | B16: =IF(A16=A15,B15+1,1) -> 11 | C16: =WEEKDAY(D16,2) -> 7 | D16: =D15+1 -> 46033 | E16: =IF(AND(OR($C16=6,$C16=7),Weekend_As_Holiday="YES",COUNTIF(Holidays!$A$6:$A$58,'Cycle Calendar'!$D16)>0),"H",IF(AND(OR($C16=6,$C16=7),Weekend_As_Holiday="NO",COUNTIF(Holidays!$A$6:$A$58,'Cycle Calendar'!$D16)>0),"W",IF(OR($C16=6,$C16=7),"W",IF(COUNTIF(Holidays!$A$6:$A$58,'Cycle Calendar'!$D16)>0,"H","R")))) -> W | F16: =E16&C16 -> W7 | H16: CYCLE 8 | I16: =COUNTIFS($D$6:$D$505,">="&Start_Date_of_Year,$D$6:$D$505,"<="&End_Date_of_Year,$A$6:$A$505,SUBSTITUTE(H16,"CYCLE ","")) -> 28 | J16: =J15+I15 -> 46244 | K16: =J16+I16-1 -> 46271 | L16: =COUNTIFS(Holidays!$A$6:$A$58,">="&'Cycle Calendar'!J16,Holidays!$A$6:$A$58,"<="&'Cycle Calendar'!K16) -> 2
A17: =IF(Calendar_Type="Calendar-Based",MONTH(D17),INT(((ROW(A12)-1)/(Days_per_Cycle+Number_Of_Weekends)))*1+1) -> 1 | B17: =IF(A17=A16,B16+1,1) -> 12 | C17: =WEEKDAY(D17,2) -> 1 | D17: =D16+1 -> 46034 | E17: =IF(AND(OR($C17=6,$C17=7),Weekend_As_Holiday="YES",COUNTIF(Holidays!$A$6:$A$58,'Cycle Calendar'!$D17)>0),"H",IF(AND(OR($C17=6,$C17=7),Weekend_As_Holiday="NO",COUNTIF(Holidays!$A$6:$A$58,'Cycle Calendar'!$D17)>0),"W",IF(OR($C17=6,$C17=7),"W",IF(COUNTIF(Holidays!$A$6:$A$58,'Cycle Calendar'!$D17)>0,"H","R")))) -> R | F17: =E17&C17 -> R1 | H17: CYCLE 9 | I17: =COUNTIFS($D$6:$D$505,">="&Start_Date_of_Year,$D$6:$D$505,"<="&End_Date_of_Year,$A$6:$A$505,SUBSTITUTE(H17,"CYCLE ","")) -> 28 | J17: =J16+I16 -> 46272 | K17: =J17+I17-1 -> 46299 | L17: =COUNTIFS(Holidays!$A$6:$A$58,">="&'Cycle Calendar'!J17,Holidays!$A$6:$A$58,"<="&'Cycle Calendar'!K17) -> 0
A18: =IF(Calendar_Type="Calendar-Based",MONTH(D18),INT(((ROW(A13)-1)/(Days_per_Cycle+Number_Of_Weekends)))*1+1) -> 1 | B18: =IF(A18=A17,B17+1,1) -> 13 | C18: =WEEKDAY(D18,2) -> 2 | D18: =D17+1 -> 46035 | E18: =IF(AND(OR($C18=6,$C18=7),Weekend_As_Holiday="YES",COUNTIF(Holidays!$A$6:$A$58,'Cycle Calendar'!$D18)>0),"H",IF(AND(OR($C18=6,$C18=7),Weekend_As_Holiday="NO",COUNTIF(Holidays!$A$6:$A$58,'Cycle Calendar'!$D18)>0),"W",IF(OR($C18=6,$C18=7),"W",IF(COUNTIF(Holidays!$A$6:$A$58,'Cycle Calendar'!$D18)>0,"H","R")))) -> R | F18: =E18&C18 -> R2 | H18: CYCLE 10 | I18: =COUNTIFS($D$6:$D$505,">="&Start_Date_of_Year,$D$6:$D$505,"<="&End_Date_of_Year,$A$6:$A$505,SUBSTITUTE(H18,"CYCLE ","")) -> 28 | J18: =J17+I17 -> 46300 | K18: =J18+I18-1 -> 46327 | L18: =COUNTIFS(Holidays!$A$6:$A$58,">="&'Cycle Calendar'!J18,Holidays!$A$6:$A$58,"<="&'Cycle Calendar'!K18) -> 1
A19: =IF(Calendar_Type="Calendar-Based",MONTH(D19),INT(((ROW(A14)-1)/(Days_per_Cycle+Number_Of_Weekends)))*1+1) -> 1 | B19: =IF(A19=A18,B18+1,1) -> 14 | C19: =WEEKDAY(D19,2) -> 3 | D19: =D18+1 -> 46036 | E19: =IF(AND(OR($C19=6,$C19=7),Weekend_As_Holiday="YES",COUNTIF(Holidays!$A$6:$A$58,'Cycle Calendar'!$D19)>0),"H",IF(AND(OR($C19=6,$C19=7),Weekend_As_Holiday="NO",COUNTIF(Holidays!$A$6:$A$58,'Cycle Calendar'!$D19)>0),"W",IF(OR($C19=6,$C19=7),"W",IF(COUNTIF(Holidays!$A$6:$A$58,'Cycle Calendar'!$D19)>0,"H","R")))) -> R | F19: =E19&C19 -> R3 | H19: CYCLE 11 | I19: =COUNTIFS($D$6:$D$505,">="&Start_Date_of_Year,$D$6:$D$505,"<="&End_Date_of_Year,$A$6:$A$505,SUBSTITUTE(H19,"CYCLE ","")) -> 28 | J19: =J18+I18 -> 46328 | K19: =J19+I19-1 -> 46355 | L19: =COUNTIFS(Holidays!$A$6:$A$58,">="&'Cycle Calendar'!J19,Holidays!$A$6:$A$58,"<="&'Cycle Calendar'!K19) -> 0
A20: =IF(Calendar_Type="Calendar-Based",MONTH(D20),INT(((ROW(A15)-1)/(Days_per_Cycle+Number_Of_Weekends)))*1+1) -> 1 | B20: =IF(A20=A19,B19+1,1) -> 15 | C20: =WEEKDAY(D20,2) -> 4 | D20: =D19+1 -> 46037 | E20: =IF(AND(OR($C20=6,$C20=7),Weekend_As_Holiday="YES",COUNTIF(Holidays!$A$6:$A$58,'Cycle Calendar'!$D20)>0),"H",IF(AND(OR($C20=6,$C20=7),Weekend_As_Holiday="NO",COUNTIF(Holidays!$A$6:$A$58,'Cycle Calendar'!$D20)>0),"W",IF(OR($C20=6,$C20=7),"W",IF(COUNTIF(Holidays!$A$6:$A$58,'Cycle Calendar'!$D20)>0,"H","R")))) -> R | F20: =E20&C20 -> R4 | H20: CYCLE 12 | I20: =COUNTIFS($D$6:$D$505,">="&Start_Date_of_Year,$D$6:$D$505,"<="&End_Date_of_Year,$A$6:$A$505,SUBSTITUTE(H20,"CYCLE ","")) -> 32 | J20: =J19+I19 -> 46356 | K20: =J20+I20-1 -> 46387 | L20: =COUNTIFS(Holidays!$A$6:$A$58,">="&'Cycle Calendar'!J20,Holidays!$A$6:$A$58,"<="&'Cycle Calendar'!K20) -> 14
A21: =IF(Calendar_Type="Calendar-Based",MONTH(D21),INT(((ROW(A16)-1)/(Days_per_Cycle+Number_Of_Weekends)))*1+1) -> 1 | B21: =IF(A21=A20,B20+1,1) -> 16 | C21: =WEEKDAY(D21,2) -> 5 | D21: =D20+1 -> 46038 | E21: =IF(AND(OR($C21=6,$C21=7),Weekend_As_Holiday="YES",COUNTIF(Holidays!$A$6:$A$58,'Cycle Calendar'!$D21)>0),"H",IF(AND(OR($C21=6,$C21=7),Weekend_As_Holiday="NO",COUNTIF(Holidays!$A$6:$A$58,'Cycle Calendar'!$D21)>0),"W",IF(OR($C21=6,$C21=7),"W",IF(COUNTIF(Holidays!$A$6:$A$58,'Cycle Calendar'!$D21)>0,"H","R")))) -> R | F21: =E21&C21 -> R5 | H21: =IF(Calendar_Type="Cycle-Based","CYCLE 13","CYCLE 1") -> CYCLE 1 | I21: =COUNTIFS($D$6:$D$505,">="&Start_Date_of_Year,$D$6:$D$505,"<="&End_Date_of_Year,$A$6:$A$505,SUBSTITUTE(H21,"CYCLE ","")) -> 32 | J21: =IF(I21=0,"",J20+I20) -> 46388 | K21: =IF(I21=0,"",J21+I21-1) -> 46419 | L21: =COUNTIFS(Holidays!$A$6:$A$58,">="&'Cycle Calendar'!J21,Holidays!$A$6:$A$58,"<="&'Cycle Calendar'!K21) -> 0
A22: =IF(Calendar_Type="Calendar-Based",MONTH(D22),INT(((ROW(A17)-1)/(Days_per_Cycle+Number_Of_Weekends)))*1+1) -> 1 | B22: =IF(A22=A21,B21+1,1) -> 17 | C22: =WEEKDAY(D22,2) -> 6 | D22: =D21+1 -> 46039 | E22: =IF(AND(OR($C22=6,$C22=7),Weekend_As_Holiday="YES",COUNTIF(Holidays!$A$6:$A$58,'Cycle Calendar'!$D22)>0),"H",IF(AND(OR($C22=6,$C22=7),Weekend_As_Holiday="NO",COUNTIF(Holidays!$A$6:$A$58,'Cycle Calendar'!$D22)>0),"W",IF(OR($C22=6,$C22=7),"W",IF(COUNTIF(Holidays!$A$6:$A$58,'Cycle Calendar'!$D22)>0,"H","R")))) -> W | F22: =E22&C22 -> W6 | H22: =IF(Calendar_Type="Cycle-Based","CYCLE 14","CYCLE 2") -> CYCLE 2 | I22: =COUNTIFS($D$6:$D$505,">="&Start_Date_of_Year,$D$6:$D$505,"<="&End_Date_of_Year,$A$6:$A$505,SUBSTITUTE(H22,"CYCLE ","")) -> 35 | J22: =IFERROR(IF(I22=0,"",J21+I21),"") -> 46420 | K22: =IFERROR(IF(I22=0,"",J22+I22-1),"") -> 46454 | L22: =COUNTIFS(Holidays!$A$6:$A$58,">="&'Cycle Calendar'!J22,Holidays!$A$6:$A$58,"<="&'Cycle Calendar'!K22) -> 0
A23: =IF(Calendar_Type="Calendar-Based",MONTH(D23),INT(((ROW(A18)-1)/(Days_per_Cycle+Number_Of_Weekends)))*1+1) -> 1 | B23: =IF(A23=A22,B22+1,1) -> 18 | C23: =WEEKDAY(D23,2) -> 7 | D23: =D22+1 -> 46040 | E23: =IF(AND(OR($C23=6,$C23=7),Weekend_As_Holiday="YES",COUNTIF(Holidays!$A$6:$A$58,'Cycle Calendar'!$D23)>0),"H",IF(AND(OR($C23=6,$C23=7),Weekend_As_Holiday="NO",COUNTIF(Holidays!$A$6:$A$58,'Cycle Calendar'!$D23)>0),"W",IF(OR($C23=6,$C23=7),"W",IF(COUNTIF(Holidays!$A$6:$A$58,'Cycle Calendar'!$D23)>0,"H","R")))) -> W | F23: =E23&C23 -> W7
A24: =IF(Calendar_Type="Calendar-Based",MONTH(D24),INT(((ROW(A19)-1)/(Days_per_Cycle+Number_Of_Weekends)))*1+1) -> 1 | B24: =IF(A24=A23,B23+1,1) -> 19 | C24: =WEEKDAY(D24,2) -> 1 | D24: =D23+1 -> 46041 | E24: =IF(AND(OR($C24=6,$C24=7),Weekend_As_Holiday="YES",COUNTIF(Holidays!$A$6:$A$58,'Cycle Calendar'!$D24)>0),"H",IF(AND(OR($C24=6,$C24=7),Weekend_As_Holiday="NO",COUNTIF(Holidays!$A$6:$A$58,'Cycle Calendar'!$D24)>0),"W",IF(OR($C24=6,$C24=7),"W",IF(COUNTIF(Holidays!$A$6:$A$58,'Cycle Calendar'!$D24)>0,"H","R")))) -> R | F24: =E24&C24 -> R1
A25: =IF(Calendar_Type="Calendar-Based",MONTH(D25),INT(((ROW(A20)-1)/(Days_per_Cycle+Number_Of_Weekends)))*1+1) -> 1 | B25: =IF(A25=A24,B24+1,1) -> 20 | C25: =WEEKDAY(D25,2) -> 2 | D25: =D24+1 -> 46042 | E25: =IF(AND(OR($C25=6,$C25=7),Weekend_As_Holiday="YES",COUNTIF(Holidays!$A$6:$A$58,'Cycle Calendar'!$D25)>0),"H",IF(AND(OR($C25=6,$C25=7),Weekend_As_Holiday="NO",COUNTIF(Holidays!$A$6:$A$58,'Cycle Calendar'!$D25)>0),"W",IF(OR($C25=6,$C25=7),"W",IF(COUNTIF(Holidays!$A$6:$A$58,'Cycle Calendar'!$D25)>0,"H","R")))) -> R | F25: =E25&C25 -> R2
A26: =IF(Calendar_Type="Calendar-Based",MONTH(D26),INT(((ROW(A21)-1)/(Days_per_Cycle+Number_Of_Weekends)))*1+1) -> 1 | B26: =IF(A26=A25,B25+1,1) -> 21 | C26: =WEEKDAY(D26,2) -> 3 | D26: =D25+1 -> 46043 | E26: =IF(AND(OR($C26=6,$C26=7),Weekend_As_Holiday="YES",COUNTIF(Holidays!$A$6:$A$58,'Cycle Calendar'!$D26)>0),"H",IF(AND(OR($C26=6,$C26=7),Weekend_As_Holiday="NO",COUNTIF(Holidays!$A$6:$A$58,'Cycle Calendar'!$D26)>0),"W",IF(OR($C26=6,$C26=7),"W",IF(COUNTIF(Holidays!$A$6:$A$58,'Cycle Calendar'!$D26)>0,"H","R")))) -> R | F26: =E26&C26 -> R3
A27: =IF(Calendar_Type="Calendar-Based",MONTH(D27),INT(((ROW(A22)-1)/(Days_per_Cycle+Number_Of_Weekends)))*1+1) -> 1 | B27: =IF(A27=A26,B26+1,1) -> 22 | C27: =WEEKDAY(D27,2) -> 4 | D27: =D26+1 -> 46044 | E27: =IF(AND(OR($C27=6,$C27=7),Weekend_As_Holiday="YES",COUNTIF(Holidays!$A$6:$A$58,'Cycle Calendar'!$D27)>0),"H",IF(AND(OR($C27=6,$C27=7),Weekend_As_Holiday="NO",COUNTIF(Holidays!$A$6:$A$58,'Cycle Calendar'!$D27)>0),"W",IF(OR($C27=6,$C27=7),"W",IF(COUNTIF(Holidays!$A$6:$A$58,'Cycle Calendar'!$D27)>0,"H","R")))) -> R | F27: =E27&C27 -> R4
A28: =IF(Calendar_Type="Calendar-Based",MONTH(D28),INT(((ROW(A23)-1)/(Days_per_Cycle+Number_Of_Weekends)))*1+1) -> 1 | B28: =IF(A28=A27,B27+1,1) -> 23 | C28: =WEEKDAY(D28,2) -> 5 | D28: =D27+1 -> 46045 | E28: =IF(AND(OR($C28=6,$C28=7),Weekend_As_Holiday="YES",COUNTIF(Holidays!$A$6:$A$58,'Cycle Calendar'!$D28)>0),"H",IF(AND(OR($C28=6,$C28=7),Weekend_As_Holiday="NO",COUNTIF(Holidays!$A$6:$A$58,'Cycle Calendar'!$D28)>0),"W",IF(OR($C28=6,$C28=7),"W",IF(COUNTIF(Holidays!$A$6:$A$58,'Cycle Calendar'!$D28)>0,"H","R")))) -> R | F28: =E28&C28 -> R5
A29: =IF(Calendar_Type="Calendar-Based",MONTH(D29),INT(((ROW(A24)-1)/(Days_per_Cycle+Number_Of_Weekends)))*1+1) -> 1 | B29: =IF(A29=A28,B28+1,1) -> 24 | C29: =WEEKDAY(D29,2) -> 6 | D29: =D28+1 -> 46046 | E29: =IF(AND(OR($C29=6,$C29=7),Weekend_As_Holiday="YES",COUNTIF(Holidays!$A$6:$A$58,'Cycle Calendar'!$D29)>0),"H",IF(AND(OR($C29=6,$C29=7),Weekend_As_Holiday="NO",COUNTIF(Holidays!$A$6:$A$58,'Cycle Calendar'!$D29)>0),"W",IF(OR($C29=6,$C29=7),"W",IF(COUNTIF(Holidays!$A$6:$A$58,'Cycle Calendar'!$D29)>0,"H","R")))) -> W | F29: =E29&C29 -> W6
A30: =IF(Calendar_Type="Calendar-Based",MONTH(D30),INT(((ROW(A25)-1)/(Days_per_Cycle+Number_Of_Weekends)))*1+1) -> 1 | B30: =IF(A30=A29,B29+1,1) -> 25 | C30: =WEEKDAY(D30,2) -> 7 | D30: =D29+1 -> 46047 | E30: =IF(AND(OR($C30=6,$C30=7),Weekend_As_Holiday="YES",COUNTIF(Holidays!$A$6:$A$58,'Cycle Calendar'!$D30)>0),"H",IF(AND(OR($C30=6,$C30=7),Weekend_As_Holiday="NO",COUNTIF(Holidays!$A$6:$A$58,'Cycle Calendar'!$D30)>0),"W",IF(OR($C30=6,$C30=7),"W",IF(COUNTIF(Holidays!$A$6:$A$58,'Cycle Calendar'!$D30)>0,"H","R")))) -> W | F30: =E30&C30 -> W7
A31: =IF(Calendar_Type="Calendar-Based",MONTH(D31),INT(((ROW(A26)-1)/(Days_per_Cycle+Number_Of_Weekends)))*1+1) -> 1 | B31: =IF(A31=A30,B30+1,1) -> 26 | C31: =WEEKDAY(D31,2) -> 1 | D31: =D30+1 -> 46048 | E31: =IF(AND(OR($C31=6,$C31=7),Weekend_As_Holiday="YES",COUNTIF(Holidays!$A$6:$A$58,'Cycle Calendar'!$D31)>0),"H",IF(AND(OR($C31=6,$C31=7),Weekend_As_Holiday="NO",COUNTIF(Holidays!$A$6:$A$58,'Cycle Calendar'!$D31)>0),"W",IF(OR($C31=6,$C31=7),"W",IF(COUNTIF(Holidays!$A$6:$A$58,'Cycle Calendar'!$D31)>0,"H","R")))) -> R | F31: =E31&C31 -> R1
A32: =IF(Calendar_Type="Calendar-Based",MONTH(D32),INT(((ROW(A27)-1)/(Days_per_Cycle+Number_Of_Weekends)))*1+1) -> 1 | B32: =IF(A32=A31,B31+1,1) -> 27 | C32: =WEEKDAY(D32,2) -> 2 | D32: =D31+1 -> 46049 | E32: =IF(AND(OR($C32=6,$C32=7),Weekend_As_Holiday="YES",COUNTIF(Holidays!$A$6:$A$58,'Cycle Calendar'!$D32)>0),"H",IF(AND(OR($C32=6,$C32=7),Weekend_As_Holiday="NO",COUNTIF(Holidays!$A$6:$A$58,'Cycle Calendar'!$D32)>0),"W",IF(OR($C32=6,$C32=7),"W",IF(COUNTIF(Holidays!$A$6:$A$58,'Cycle Calendar'!$D32)>0,"H","R")))) -> R | F32: =E32&C32 -> R2
A33: =IF(Calendar_Type="Calendar-Based",MONTH(D33),INT(((ROW(A28)-1)/(Days_per_Cycle+Number_Of_Weekends)))*1+1) -> 1 | B33: =IF(A33=A32,B32+1,1) -> 28 | C33: =WEEKDAY(D33,2) -> 3 | D33: =D32+1 -> 46050 | E33: =IF(AND(OR($C33=6,$C33=7),Weekend_As_Holiday="YES",COUNTIF(Holidays!$A$6:$A$58,'Cycle Calendar'!$D33)>0),"H",IF(AND(OR($C33=6,$C33=7),Weekend_As_Holiday="NO",COUNTIF(Holidays!$A$6:$A$58,'Cycle Calendar'!$D33)>0),"W",IF(OR($C33=6,$C33=7),"W",IF(COUNTIF(Holidays!$A$6:$A$58,'Cycle Calendar'!$D33)>0,"H","R")))) -> R | F33: =E33&C33 -> R3
A34: =IF(Calendar_Type="Calendar-Based",MONTH(D34),INT(((ROW(A29)-1)/(Days_per_Cycle+Number_Of_Weekends)))*1+1) -> 1 | B34: =IF(A34=A33,B33+1,1) -> 29 | C34: =WEEKDAY(D34,2) -> 4 | D34: =D33+1 -> 46051 | E34: =IF(AND(OR($C34=6,$C34=7),Weekend_As_Holiday="YES",COUNTIF(Holidays!$A$6:$A$58,'Cycle Calendar'!$D34)>0),"H",IF(AND(OR($C34=6,$C34=7),Weekend_As_Holiday="NO",COUNTIF(Holidays!$A$6:$A$58,'Cycle Calendar'!$D34)>0),"W",IF(OR($C34=6,$C34=7),"W",IF(COUNTIF(Holidays!$A$6:$A$58,'Cycle Calendar'!$D34)>0,"H","R")))) -> R | F34: =E34&C34 -> R4
... A36: =IF(Calendar_Type="Calendar-Based",MONTH(D36),INT(((ROW(A31)-1)/(Days_per_Cycle+Number_Of_Weekends)))*1+1) -> 1 | B36: =IF(A36=A35,B35+1,1) -> 31 | C36: =WEEKDAY(D36,2) -> 6 | D36: =D35+1 -> 46053 | E36: =IF(AND(OR($C36=6,$C36=7),Weekend_As_Holiday="YES",COUNTIF(Holidays!$A$6:$A$58,'Cycle Calendar'!$D36)>0),"H",IF(AND(OR($C36=6,$C36=7),Weekend_As_Holiday="NO",COUNTIF(Holidays!$A$6:$A$58,'Cycle Calendar'!$D36)>0),"W",IF(OR($C36=6,$C36=7),"W",IF(COUNTIF(Holidays!$A$6:$A$58,'Cycle Calendar'!$D36)>0,"H","R")))) -> W | F36: =E36&C36 -> W6
A37: 1 | B37: =IF(A37=A36,B36+1,1) -> 32 | C37: =WEEKDAY(D37,2) -> 7 | D37: =D36+1 -> 46054 | E37: =IF(AND(OR($C37=6,$C37=7),Weekend_As_Holiday="YES",COUNTIF(Holidays!$A$6:$A$58,'Cycle Calendar'!$D37)>0),"H",IF(AND(OR($C37=6,$C37=7),Weekend_As_Holiday="NO",COUNTIF(Holidays!$A$6:$A$58,'Cycle Calendar'!$D37)>0),"W",IF(OR($C37=6,$C37=7),"W",IF(COUNTIF(Holidays!$A$6:$A$58,'Cycle Calendar'!$D37)>0,"H","R")))) -> W | F37: =E37&C37 -> W7
A38: =IF(Calendar_Type="Calendar-Based",MONTH(D38),INT(((ROW(A33)-1)/(Days_per_Cycle+Number_Of_Weekends)))*1+1) -> 2 | B38: =IF(A38=A37,B37+1,1) -> 1 | C38: =WEEKDAY(D38,2) -> 1 | D38: =D37+1 -> 46055 | E38: =IF(AND(OR($C38=6,$C38=7),Weekend_As_Holiday="YES",COUNTIF(Holidays!$A$6:$A$58,'Cycle Calendar'!$D38)>0),"H",IF(AND(OR($C38=6,$C38=7),Weekend_As_Holiday="NO",COUNTIF(Holidays!$A$6:$A$58,'Cycle Calendar'!$D38)>0),"W",IF(OR($C38=6,$C38=7),"W",IF(COUNTIF(Holidays!$A$6:$A$58,'Cycle Calendar'!$D38)>0,"H","R")))) -> H | F38: =E38&C38 -> H1
A39: =IF(Calendar_Type="Calendar-Based",MONTH(D39),INT(((ROW(A34)-1)/(Days_per_Cycle+Number_Of_Weekends)))*1+1) -> 2 | B39: =IF(A39=A38,B38+1,1) -> 2 | C39: =WEEKDAY(D39,2) -> 2 | D39: =D38+1 -> 46056 | E39: =IF(AND(OR($C39=6,$C39=7),Weekend_As_Holiday="YES",COUNTIF(Holidays!$A$6:$A$58,'Cycle Calendar'!$D39)>0),"H",IF(AND(OR($C39=6,$C39=7),Weekend_As_Holiday="NO",COUNTIF(Holidays!$A$6:$A$58,'Cycle Calendar'!$D39)>0),"W",IF(OR($C39=6,$C39=7),"W",IF(COUNTIF(Holidays!$A$6:$A$58,'Cycle Calendar'!$D39)>0,"H","R")))) -> H | F39: =E39&C39 -> H2
A40: =IF(Calendar_Type="Calendar-Based",MONTH(D40),INT(((ROW(A35)-1)/(Days_per_Cycle+Number_Of_Weekends)))*1+1) -> 2 | B40: =IF(A40=A39,B39+1,1) -> 3 | C40: =WEEKDAY(D40,2) -> 3 | D40: =D39+1 -> 46057 | E40: =IF(AND(OR($C40=6,$C40=7),Weekend_As_Holiday="YES",COUNTIF(Holidays!$A$6:$A$58,'Cycle Calendar'!$D40)>0),"H",IF(AND(OR($C40=6,$C40=7),Weekend_As_Holiday="NO",COUNTIF(Holidays!$A$6:$A$58,'Cycle Calendar'!$D40)>0),"W",IF(OR($C40=6,$C40=7),"W",IF(COUNTIF(Holidays!$A$6:$A$58,'Cycle Calendar'!$D40)>0,"H","R")))) -> H | F40: =E40&C40 -> H3
A41: =IF(Calendar_Type="Calendar-Based",MONTH(D41),INT(((ROW(A36)-1)/(Days_per_Cycle+Number_Of_Weekends)))*1+1) -> 2 | B41: =IF(A41=A40,B40+1,1) -> 4 | C41: =WEEKDAY(D41,2) -> 4 | D41: =D40+1 -> 46058 | E41: =IF(AND(OR($C41=6,$C41=7),Weekend_As_Holiday="YES",COUNTIF(Holidays!$A$6:$A$58,'Cycle Calendar'!$D41)>0),"H",IF(AND(OR($C41=6,$C41=7),Weekend_As_Holiday="NO",COUNTIF(Holidays!$A$6:$A$58,'Cycle Calendar'!$D41)>0),"W",IF(OR($C41=6,$C41=7),"W",IF(COUNTIF(Holidays!$A$6:$A$58,'Cycle Calendar'!$D41)>0,"H","R")))) -> H | F41: =E41&C41 -> H4
...

Sheet Holidays
A1: List of Holidays for 2025
A2: Date | B2: Day of Week | C2: Holiday
A3: (type: date | size: 10) | B3: (type: integer | size: 8) | C3: (type: text | size: 50)
A4: format: YYYY-MM-DD | B4: Monday, Tuesday, etc. | C4: (e.g. New Year's Day, Good Friday, Christmas Day, etc.)
A5: Valid Characters: Numeric , / | B5: Valid Characters: Alpha | C5: Valid Characters: Alphanumeric, ÑñÉé .,'/()&-@#
A6: 46023 | B6: =IF(A6="","",IFERROR(TEXT(A6,"dddd"),"Invalid Date")) -> Thursday | C6: New Year's Day
A7: 46070 | B7: =IF(A7="","",IFERROR(TEXT(A7,"dddd"),"Invalid Date")) -> Tuesday | C7: Chinese New Year
A8: 46114 | B8: =IF(A8="","",IFERROR(TEXT(A8,"dddd"),"Invalid Date")) -> Thursday | C8: Maundy Thursday
A9: 46115 | B9: =IF(A9="","",IFERROR(TEXT(A9,"dddd"),"Invalid Date")) -> Friday | C9: Good Friday
A10: 46116 | B10: =IF(A10="","",IFERROR(TEXT(A10,"dddd"),"Invalid Date")) -> Saturday | C10: Black Saturday
A11: 46121 | B11: =IF(A11="","",IFERROR(TEXT(A11,"dddd"),"Invalid Date")) -> Thursday | C11: Araw ng Kagitingan
A12: 46143 | B12: =IF(A12="","",IFERROR(TEXT(A12,"dddd"),"Invalid Date")) -> Friday | C12: Labor Day
A13: 46185 | B13: =IF(A13="","",IFERROR(TEXT(A13,"dddd"),"Invalid Date")) -> Friday | C13: Independence Day
A14: 46255 | B14: =IF(A14="","",IFERROR(TEXT(A14,"dddd"),"Invalid Date")) -> Friday | C14: Ninoy Aquino Day
A15: 46265 | B15: =IF(A15="","",IFERROR(TEXT(A15,"dddd"),"Invalid Date")) -> Monday | C15: National Heroes Day
A16: 46327 | B16: =IF(A16="","",IFERROR(TEXT(A16,"dddd"),"Invalid Date")) -> Sunday | C16: All Soul's Day
A17: 46356 | B17: =IF(A17="","",IFERROR(TEXT(A17,"dddd"),"Invalid Date")) -> Monday | C17: Bonifacio Day
... A43: 46387 | B43: =IF(A43="","",IFERROR(TEXT(A43,"dddd"),"Invalid Date")) -> Thursday | C43: Medchoice Shutdown
B44: =IF(A44="","",IFERROR(TEXT(A44,"dddd"),"Invalid Date"))
B45: =IF(A45="","",IFERROR(TEXT(A45,"dddd"),"Invalid Date"))
B46: =IF(A46="","",IFERROR(TEXT(A46,"dddd"),"Invalid Date"))
B47: =IF(A47="","",IFERROR(TEXT(A47,"dddd"),"Invalid Date"))
B48: =IF(A48="","",IFERROR(TEXT(A48,"dddd"),"Invalid Date"))
B49: =IF(A49="","",IFERROR(TEXT(A49,"dddd"),"Invalid Date"))
B50: =IF(A50="","",IFERROR(TEXT(A50,"dddd"),"Invalid Date"))
B51: =IF(A51="","",IFERROR(TEXT(A51,"dddd"),"Invalid Date"))
B52: =IF(A52="","",IFERROR(TEXT(A52,"dddd"),"Invalid Date"))
B53: =IF(A53="","",IFERROR(TEXT(A53,"dddd"),"Invalid Date"))
B54: =IF(A54="","",IFERROR(TEXT(A54,"dddd"),"Invalid Date"))
B55: =IF(A55="","",IFERROR(TEXT(A55,"dddd"),"Invalid Date"))
... B58: =IF(A58="","",IFERROR(TEXT(A58,"dddd"),"Invalid Date"))

Sheet Settings
A2: Field Name | B2: Settings | C2: Settings Guide | D2: Remarks
A3: Calendar Type | B3: Calendar-Based | C3: Calendar-Based: Number of days is based on the calendar month Cycle-Based: Number of days is based on Days-per-Cycle value | D3: Select Calendar-Based if client uses calendar months for their operations (i.e. January = 31 days, February = 28/29 days, etc.). Select Cycle-Based if client uses a fixed number of days for their operations (e.g. 20 days cycle, 2-week cycle, etc.)
A4: Days per Cycle | B4: 20 | C4: Fixed number of days included in a cycle | D4: Refers to a fixed number of days included for a given cycle if the Calendar Type is "Cycle-Based". This value has no effect if Calendar Type is set to "Calendar-Based"
A5: Start Date of Year | B5: 46023 | C5: Start date is either January 1, or the starting date of a fiscal year | D5: If client is using a Calendar year, then start date should be January 1, otherwise, if using a Fiscal year, then specify the start date of the Fiscal year
A6: End Date of Year | B6: 46387 | C6: End date is either December 31, or the last date of a fiscal year | D6: If client is using a Calendar year, then end date should be December 31, otherwise, if using a Fiscal year, then specify the end date of the client's Fiscal year
A7: Cycle Header | B7: 2026 | C7: The applicable year for the Cycle Calendar | D7: The Cycle Header label will be prefixed with "CY" plus the value specified in the 'Cycle_Header' named range. This is auto-calculated from the year of the Start Date
A8: Weekend as Holiday | B8: NO | C8: Yes - Weekend date that falls on a holiday will be tagged as "H" No - Weekend date that falls on a holiday will be tagged as "W" | D8: Determines what will be the TYPE to be assigned for weekend dates that falll also on a holiday
A9: Number Of Weekends | B9: =Days_per_Cycle/5*2 -> 8 | C9: The value is auto-computed based on the specified number of Days per Cycle divided by 5 and multiplied by 2 | D9: The "Number of Weekends" setting is used in the formula of the "Cycle number" that determines the total count of weekend dates that will be included or to be added to the "Days per Cycle" value in order to establish the inclusive dates of a given cycle
